Workbook

Sheet Résumé
B25: Week1 -> Week2 | L25: Week3 -> Week6 | AF25: Week7 -> Week8 | AZ25: Week11 -> Week12 | BJ25: Week13 -> Week 16 | CD25: Week17 -> Week20 | CX25: Week21 -> Week24
A26: SPRINT 1
A27: SPRINT 2
A28: SPRINT 3
A29: SPRINT 4
A30: SPRINT5
A31: SPRINT6
A32: SPRINT7 | B32: Charge idéal

Sheet Backlog
A21: ID | B21: User Story | C21: Critères d’acceptation | D21: Priorité (MoSCoW) | E21: Story point
A22: US001 | B22: En tant qu’utilisateur, je veux créer un compte avec une adresse mail et mot de passe afin d’accéder à l’application. | C22: - Formulaire création compte | D22: Must | E22: 2
C23: - Validation email
C24: - Mot de passe conforme aux règles de sécurité
A25: US002 | B25: En tant qu’utilisateur, je veux me connecter à l’application avec mon email et mot de passe afin d’accéder à mon compte. | C25: - Formulaire connexion | D25: Must | E25: 2
C26: - Gestion des erreurs
C27: - Récupération mot de passe
A28: US003 | B28: En tant qu'utilisateur, je veux pouvoir gérer mon compte (éditer mon profil, supprimer mon compte) | C28: - Modification des informations personnelles | D28: Must | E28: 2
C29: - Suppression du compte
C30: - Confirmation avant suppression
A31: US004 | B31: En tant qu’utilisateur, je veux me prendre en photo et charger mes photos sur l'application afin de constituer ma garde-robe virtuelle. | C31: - Prise de photo via l’application | D31: Must | E31: 8
C32: - Gestion des albums / catégories
C33: - Visualisation des photos
A34: US005 | B34: En tant qu’utilisateur, je veux que l’IA me propose des vêtements correspondant à ma garde-robe afin de découvrir des articles adaptés à mes goûts. | C34: - Génération de recommandations par l'algorithme (min: 5) | D34: Must | E34: 13
C35: - Affichage clair des recommandation (photo)
A36: US006 | B36: En tant qu’utilisateur, je veux visualiser le vêtement recommandé sur ma photo afin de juger de l’adéquation. | C36: - Superposition du vêtement sur la photo | D36: Must | E36: 13
C37: - Option de sauvegarde du vêtement (favoris)
A38: US007 | B38: En tant qu’utilisateur, je veux pouvoir changer la couleur ou le style du vêtement recommandé afin de personnaliser les suggestions. | C38: - Sélecteur de couleurs et styles | D38: Should | E38: 5
C39: - Visualisation du changement en temps réel
A40: US008 | B40: En tant qu’utilisateur, je veux définir mes styles préférés afin que l’IA me propose des recommandations plus adaptées. | C40: - Liste de styles proposés | D40: Could | E40: 2
C41: - Possibilité de sélectionner plusieurs styles
C42: - Option pour prioriser les styles
A43: US009 | B43: En tant qu’utilisateur, je veux référencer mes marques préférées afin que l’IA priorise ces marques dans ses recommandations. | C43: - Liste de marques vendues par Fashion-Insta | D43: Could | E43: 2
C44: - Possibilité de selectionner plusieurs marques vendues par Fashion-Insta
C45: - Option pour prioriser les marques
A46: US0010 | B46: En tant qu’utilisateur, je veux référencer des blogs, sites, ou influenceur(se)s afin que l’IA intègre ces sources dans ses recommandations. | C46: - Formulaire pour ajouter / supprimer des sources | D46: Could | E46: 2
C47: - Option pour prioriser les sources
A48: US011 | B48: En tant qu’utilisateur, je veux recevoir des suggestions d’accessoires assortis afin de compléter mes tenues. | C48: - IA proposant des accessoires associés (chaussures, sacs, etc.) | D48: Could | E48: 8
C49: - Affichage des accessoires dans la même interface que les vêtements
A50: US012 | B50: En tant qu’utilisateur, je veux pouvoir utiliser des filtres avancés (prix, couleur, taille, disponibilité, etc.) afin d’affiner mes recherches. | C50: - Système de filtres multiples (prix, couleurs, style, etc.) | D50: Could | E50: 3
C51: - Tri dynamique des résultats
C52: - Réinitialisation facile des filtres
A53: US013 | B53: En tant qu’utilisateur, je veux consulter l’historique de mes recommandations et achats afin de pouvoir retrouver d'anciennes recommandations, | C53: - Liste des recommandations précédentes | D53: Could | E53: 3
C54: - Filtrage par date / type
A55: US014 | B55: En tant qu’utilisateur, je veux pouvoir donner un avis sur la pertinence des recommandations afin d’améliorer la qualité du service. | C55: - Système de notation (ex : étoiles) | D55: Should | E55: 3
C56: - Possibilité de commenter
C57: - Historique des avis
A58: US015 | B58: En tant qu’utilisateur, je veux pouvoir ajouter des produits au panier et valider une commande afin de réaliser un achat. | C58: - Ajout au panier | D58: Must | E58: 5
C59: - Validation commande
C60: - Choix de la livraison
...

Sheet Planning
A13: Sprint | B13: Durée | C13: User Stories | D13: Story Point | E13: Objectifs | F13: Profils impliqués | G13: Estimation charge (jours)
A14: Sprint 1 | B14: 2 semaines | C14: US04 | D14: 8 | E14: Gestion des photos & garde-robe virtuelle | F14: Dev Mobile | G14: 7
F15: Data Engineer | G15: 5
F16: UX/UI | G16: 5
F17: QA | G17: 3
A18: Sprint 2 | B18: 4 semaines | C18: US05 | D18: 13 | E18: Recommandation de vêtements grâce à l'IA | F18: Dev Mobile | G18: 12
F19: Data Scientist | G19: 15
F20: Data Engineer | G20: 8
F21: QA | G21: 5
A22: Sprint 3 | B22: 4 semaines | C22: US06 | D22: 13 | E22: Affichage des recommandations sur les photo des utilisateurs | F22: Dev Mobile | G22: 12
F23: Data Scientist | G23: 15
F24: Data Engineer | G24: 8
F25: QA | G25: 5
A26: Sprint 4 | B26: 2 semaines | C26: US01, US02, US03 | D26: 6 | E26: Compte utilisateur & authentification | F26: Dev Mobile | G26: 7
F27: UX/UI | G27: 5
F28: QA | G28: 4
A29: Sprint 5 | B29: 4 semaines | C29: US14, US015, US16 | D29: 13 | E29: panier & paiement, RGPD + avis | F29: Dev Mobile | G29: 15
F30: Data Engineer | G30: 10
F31: UX/UI | G31: 10
F32: QA | G32: 8
A33: Sprint 6 | B33: 4 semaines | C33: US07, US008, US009, US012 | D33: 12 | E33: Personnalisation des recommandations (couleur, style, marques, filtres avancés) | F33: Dev Mobile | G33: 15
F34: Data Engineer | G34: 10
F35: UX/UI | G35: 10
F36: QA | G36: 8
A37: Sprint 7 | B37: 4 semaines | C37: US010, US11, US13 | D37: 13 | E37: Personnalisation des recommandations (sources externes, recommandation d'accessoirs assortis) + intégration d'un historique | F37: Dev Mobile | G37: 10
F38: Data Scientist | G38: 15
F39: Data Engineer | G39: 10
F40: UX/UI | G40: 12
F41: QA | G41: 8
C94: 78 | D94: 0 | E94: =78/24 -> 3.25 | F94: 78
C95: =78 - D95 * $E$94 -> 74.75 | D95: 1 | F95: 74
C96: =78 - D96 * $E$94 -> 71.5 | D96: 2 | F96: 71
C97: =78 - D97 * $E$94 -> 68.25 | D97: 3 | F97: 68
C98: =78 - D98 * $E$94 -> 65 | D98: 4 | F98: 67
C99: =78 - D99 * $E$94 -> 61.75 | D99: 5 | F99: 63
C100: =78 - D100 * $E$94 -> 58.5 | D100: 6 | F100: 60
C101: =78 - D101 * $E$94 -> 55.25 | D101: 7 | F101: 58
C102: =78 - D102 * $E$94 -> 52 | D102: 8 | F102: 54
C103: =78 - D103 * $E$94 -> 48.75 | D103: 9 | F103: 51
C104: =78 - D104 * $E$94 -> 45.5 | D104: 10 | F104: 48
...

Sheet Budget et bénéfices
A1: Plannification des coûts et bénéfices attendus
A14: Plannification coût des ressources humaines | F14: Plannification des bénéfices attendus
A15: Rôle | B15: Temps estimé | C15: Taux journalier | D15: Coût total | G15: Période | H15: Utilisateurs | I15: % Utilisateur actifs | J15: Gains brutes (€) | K15: Gains nets (€) | L15: Gain cumulé (€) | M15: Coût (€) | N15: Coût cumulé (€) | O15: Bénéfice (€) | P15: Bénéfice cumulé (€)
A16: SCRUM master | B16: 50 | C16: 300 | D16: =C16*B16 -> 15000 | F16: Développement | G16: Mois 1 | H16: 0 | I16: 0 | J16: 0 | K16: =J16*0.65 -> 0 | L16: =SUM($K$15:K15) -> 0 | M16: =D49+D50 -> 22616.81 | N16: =SUM($M$16:M16) -> 22616.81 | O16: =K16-M16 -> -22616.81 | P16: =SUM($O$16:O16) -> -22616.81
A17: Product Owner | B17: 50 | C17: 330 | D17: =C17*B17 -> 16500 | G17: Mois 2 | H17: 100 | I17: 1 | J17: 0 | K17: =J17*0.65 -> 0 | L17: =SUM($K$15:K16) -> 0 | M17: =D49+D50 -> 22616.81 | N17: =SUM($M$16:M17) -> 45233.62 | O17: =K17-M17 -> -22616.81 | P17: =SUM($O$16:O17) -> -45233.62
A18: Developpeur mobile | B18: =Planning!G26+Planning!G14+Planning!G18+Planning!G29+Planning!G33+Planning!G22 -> 68 | C18: 300 | D18: =C18*B18 -> 20400 | G18: Mois 3 | H18: 230 | I18: 0.45 | J18: 0 | K18: =J18*0.65 -> 0 | L18: =SUM($K$15:K17) -> 0 | M18: =D49+D50 -> 22616.81 | N18: =SUM($M$16:M18) -> 67850.43 | O18: =K18-M18 -> -22616.81 | P18: =SUM($O$16:O18) -> -67850.43
A19: Data engineer | B19: =Planning!G15+Planning!G20+Planning!G24+Planning!G30+Planning!G34+Planning!G39 -> 51 | C19: 330 | D19: =C19*B19 -> 16830 | G19: Mois 4 | H19: 400 | I19: 0,,42 | J19: 0 | K19: =J19*0.65 -> 0 | L19: =SUM($K$15:K18) -> 0 | M19: =D49+D50 -> 22616.81 | N19: =SUM($M$16:M19) -> 90467.24 | O19: =K19-M19 -> -22616.81 | P19: =SUM($O$16:O19) -> -90467.24
A20: UX/UI designer | B20: =Planning!G27+Planning!G16+Planning!G31+Planning!G35 -> 30 | C20: 270 | D20: =C20*B20 -> 8100 | G20: Mois 5 | H20: 700 | I20: 0.4 | J20: =800 * 30 -> 24000 | K20: =J20*0.65 -> 15600 | L20: =SUM($K$15:K20) -> 15600 | M20: =D49+D50 -> 22616.81 | N20: =SUM($M$16:M20) -> 113084.05 | O20: =K20-M20 -> -7016.81 | P20: =SUM($O$16:O20) -> -97484.05
A21: Data scientist (junior) | B21: =Planning!G19+Planning!G38+Planning!G23 -> 45 | C21: 220 | D21: =C21*B21 -> 9900 | F21: Année 1 post développement | G21: Mois 6 | H21: 1200 | I21: 0.35 | J21: =(H21-H20) * 30 + (H20 * I21) * 50 -> 27250 | K21: =J21*0.65 -> 17712.5 | L21: =SUM($K$15:K21) -> 33312.5 | M21: =$D$51 + IF(H21 <= 10000,$P$98, IF( H21 <= 25000,$P$101, $P$104)) + IF(H21 <= 10000,$P$107, IF( H21 <= 25000,$P$109,$P$111)) + IF(H21 <= 10000,$P$113, IF( H21 <= 25000,$P$114,$P$115)) + IF(H21 <= 10000,$P$116, IF( H21 <= 25000,$P$117,$P$118)) +$P$119 + IF(H21 <= 10000,$P$120, IF( H21 <= 25000,$P$121, $P$122)) -> 3810.3315 | N21: =SUM($M$16:M21) -> 116894.38 | O21: =K21-M21 -> 13902.168 | P21: =SUM($O$16:O21) -> -83581.882
A22: Sous traitant IA (40% du temps du DS) | B22: =B21*0.4 -> 18 | C22: 600 | D22: =B22*C22 -> 10800 | G22: Mois 7 | H22: 1900 | I22: 0.3 | J22: =(H22-H21) * 30 + (H21 * I22) * 50 -> 39000 | K22: =J22*0.65 -> 25350 | L22: =SUM($K$15:K22) -> 58662.5 | M22: =$D$51 + IF(H22 <= 10000,$P$98, IF( H22 <= 25000,$P$101, $P$104)) + IF(H22 <= 10000,$P$107, IF( H22 <= 25000,$P$109,$P$111)) + IF(H22 <= 10000,$P$113, IF( H22 <= 25000,$P$114,$P$115)) + IF(H22 <= 10000,$P$116, IF( H22 <= 25000,$P$117,$P$118)) +$P$119 + IF(H22 <= 10000,$P$120, IF( H22 <= 25000,$P$121, $P$122)) -> 3810.3315 | N22: =SUM($M$16:M22) -> 120704.71 | O22: =K22-M22 -> 21539.668 | P22: =SUM($O$16:O22) -> -62042.213
A23: Testeur QA | B23: =Planning!G36+Planning!G32+Planning!G21+Planning!G17+Planning!G28+Planning!G25+Planning!G36 -> 41 | C23: 240 | D23: =C23*B23 -> 9840 | G23: Mois 8 | H23: 2800 | I23: 0.25 | J23: =(H23-H22) * 30 + (H22 * I23) * 50 -> 50750 | K23: =J23*0.65 -> 32987.5 | L23: =SUM($K$15:K23) -> 91650 | M23: =$D$51 + IF(H23 <= 10000,$P$98, IF( H23 <= 25000,$P$101, $P$104)) + IF(H23 <= 10000,$P$107, IF( H23 <= 25000,$P$109,$P$111)) + IF(H23 <= 10000,$P$113, IF( H23 <= 25000,$P$114,$P$115)) + IF(H23 <= 10000,$P$116, IF( H23 <= 25000,$P$117,$P$118)) +$P$119 + IF(H23 <= 10000,$P$120, IF( H23 <= 25000,$P$121, $P$122)) -> 3810.3315 | N23: =SUM($M$16:M23) -> 124515.04 | O23: =K23-M23 -> 29177.168 | P23: =SUM($O$16:O23) -> -32865.045
A24: Délégué à la protection des données | B24: 10 | C24: 300 | D24: =C24*B24 -> 3000 | G24: Mois 9 | H24: 4000 | I24: 0.2 | J24: =(H24-H23) * 30 + (H23 * I24) * 50 -> 64000 | K24: =J24*0.65 -> 41600 | L24: =SUM($K$15:K24) -> 133250 | M24: =$D$51 + IF(H24 <= 10000,$P$98, IF( H24 <= 25000,$P$101, $P$104)) + IF(H24 <= 10000,$P$107, IF( H24 <= 25000,$P$109,$P$111)) + IF(H24 <= 10000,$P$113, IF( H24 <= 25000,$P$114,$P$115)) + IF(H24 <= 10000,$P$116, IF( H24 <= 25000,$P$117,$P$118)) +$P$119 + IF(H24 <= 10000,$P$120, IF( H24 <= 25000,$P$121, $P$122)) -> 3810.3315 | N24: =SUM($M$16:M24) -> 128325.38 | O24: =K24-M24 -> 37789.668 | P24: =SUM($O$16:O24) -> 4924.624
A25: Total | D25: =SUM(D16:D24) -> 110370 | G25: Mois 10 | H25: 5500 | I25: 0.15 | J25: =(H25-H24) * 30 + (H24 * I25) * 50 -> 75000 | K25: =J25*0.65 -> 48750 | L25: =SUM($K$15:K25) -> 182000 | M25: =$D$51 + IF(H25 <= 10000,$P$98, IF( H25 <= 25000,$P$101, $P$104)) + IF(H25 <= 10000,$P$107, IF( H25 <= 25000,$P$109,$P$111)) + IF(H25 <= 10000,$P$113, IF( H25 <= 25000,$P$114,$P$115)) + IF(H25 <= 10000,$P$116, IF( H25 <= 25000,$P$117,$P$118)) +$P$119 + IF(H25 <= 10000,$P$120, IF( H25 <= 25000,$P$121, $P$122)) -> 3810.3315 | N25: =SUM($M$16:M25) -> 132135.71 | O25: =K25-M25 -> 44939.668 | P25: =SUM($O$16:O25) -> 49864.292
A26: Plannification coût des ressources matérielles et logistiques | G26: Mois 11 | H26: 7300 | I26: 0.1 | J26: =(H26-H25) * 30 + (H25 * I26) * 50 -> 81500 | K26: =J26*0.65 -> 52975 | L26: =SUM($K$15:K26) -> 234975 | M26: =$D$51 + IF(H26 <= 10000,$P$98, IF( H26 <= 25000,$P$101, $P$104)) + IF(H26 <= 10000,$P$107, IF( H26 <= 25000,$P$109,$P$111)) + IF(H26 <= 10000,$P$113, IF( H26 <= 25000,$P$114,$P$115)) + IF(H26 <= 10000,$P$116, IF( H26 <= 25000,$P$117,$P$118)) +$P$119 + IF(H26 <= 10000,$P$120, IF( H26 <= 25000,$P$121, $P$122)) -> 3810.3315 | N26: =SUM($M$16:M26) -> 135946.04 | O26: =K26-M26 -> 49164.668 | P26: =SUM($O$16:O26) -> 99028.961
G27: Mois 12 | H27: 9300 | I27: 0.1 | J27: =(H27-H26) * 30 + (H26 * I27) * 50 -> 96500 | K27: =J27*0.65 -> 62725 | L27: =SUM($K$15:K27) -> 297700 | M27: =$D$51 + IF(H27 <= 10000,$P$98, IF( H27 <= 25000,$P$101, $P$104)) + IF(H27 <= 10000,$P$107, IF( H27 <= 25000,$P$109,$P$111)) + IF(H27 <= 10000,$P$113, IF( H27 <= 25000,$P$114,$P$115)) + IF(H27 <= 10000,$P$116, IF( H27 <= 25000,$P$117,$P$118)) +$P$119 + IF(H27 <= 10000,$P$120, IF( H27 <= 25000,$P$121, $P$122)) -> 3810.3315 | N27: =SUM($M$16:M27) -> 139756.37 | O27: =K27-M27 -> 58914.668 | P27: =SUM($O$16:O27) -> 157943.63
A28: Type | B28: Détail | D28: Coût mensuel | G28: Mois 13 | H28: 11500 | I28: 0.1 | J28: =(H28-H27) * 30 + (H27 * I28) * 50 -> 112500 | K28: =J28*0.65 -> 73125 | L28: =SUM($K$15:K28) -> 370825 | M28: =$D$51 + IF(H28 <= 10000,$P$98, IF( H28 <= 25000,$P$101, $P$104)) + IF(H28 <= 10000,$P$107, IF( H28 <= 25000,$P$109,$P$111)) + IF(H28 <= 10000,$P$113, IF( H28 <= 25000,$P$114,$P$115)) + IF(H28 <= 10000,$P$116, IF( H28 <= 25000,$P$117,$P$118)) +$P$119 + IF(H28 <= 10000,$P$120, IF( H28 <= 25000,$P$121, $P$122)) -> 4182.0515 | N28: =SUM($M$16:M28) -> 143938.42 | O28: =K28-M28 -> 68942.948 | P28: =SUM($O$16:O28) -> 226886.58
G29: Mois 14 | H29: 13800 | I29: 0.1 | J29: =(H29-H28) * 30 + (H28 * I29) * 50 -> 126500 | K29: =J29*0.65 -> 82225 | L29: =SUM($K$15:K29) -> 453050 | M29: =$D$51 + IF(H29 <= 10000,$P$98, IF( H29 <= 25000,$P$101, $P$104)) + IF(H29 <= 10000,$P$107, IF( H29 <= 25000,$P$109,$P$111)) + IF(H29 <= 10000,$P$113, IF( H29 <= 25000,$P$114,$P$115)) + IF(H29 <= 10000,$P$116, IF( H29 <= 25000,$P$117,$P$118)) +$P$119 + IF(H29 <= 10000,$P$120, IF( H29 <= 25000,$P$121, $P$122)) -> 4182.0515 | N29: =SUM($M$16:M29) -> 148120.47 | O29: =K29-M29 -> 78042.948 | P29: =SUM($O$16:O29) -> 304929.53
A30: Ressources entrainement modèle | G30: Mois 15 | H30: 15200 | I30: 0.1 | J30: =(H30-H29) * 30 + (H29 * I30) * 50 -> 111000 | K30: =J30*0.65 -> 72150 | L30: =SUM($K$15:K30) -> 525200 | M30: =$D$51 + IF(H30 <= 10000,$P$98, IF( H30 <= 25000,$P$101, $P$104)) + IF(H30 <= 10000,$P$107, IF( H30 <= 25000,$P$109,$P$111)) + IF(H30 <= 10000,$P$113, IF( H30 <= 25000,$P$114,$P$115)) + IF(H30 <= 10000,$P$116, IF( H30 <= 25000,$P$117,$P$118)) +$P$119 + IF(H30 <= 10000,$P$120, IF( H30 <= 25000,$P$121, $P$122)) -> 4182.0515 | N30: =SUM($M$16:M30) -> 152302.53 | O30: =K30-M30 -> 67967.948 | P30: =SUM($O$16:O30) -> 372897.47
A31: Azure Machine learning | B31: Entrainement modèle IA, déploiement modèle IA, GPU, CPU | D31: =P90 -> 360 | G31: Mois 16 | H31: 16400 | I31: 0.1 | J31: =(H31-H30) * 30 + (H30 * I31) * 50 -> 112000 | K31: =J31*0.65 -> 72800 | L31: =SUM($K$15:K31) -> 598000 | M31: =$D$51 + IF(H31 <= 10000,$P$98, IF( H31 <= 25000,$P$101, $P$104)) + IF(H31 <= 10000,$P$107, IF( H31 <= 25000,$P$109,$P$111)) + IF(H31 <= 10000,$P$113, IF( H31 <= 25000,$P$114,$P$115)) + IF(H31 <= 10000,$P$116, IF( H31 <= 25000,$P$117,$P$118)) +$P$119 + IF(H31 <= 10000,$P$120, IF( H31 <= 25000,$P$121, $P$122)) -> 4182.0515 | N31: =SUM($M$16:M31) -> 156484.58 | O31: =K31-M31 -> 68617.948 | P31: =SUM($O$16:O31) -> 441515.42
G32: Mois 17 | H32: 17500 | I32: 0.1 | J32: =(H32-H31) * 30 + (H31 * I32) * 50 -> 115000 | K32: =J32*0.65 -> 74750 | L32: =SUM($K$15:K32) -> 672750 | M32: =$D$51 + IF(H32 <= 10000,$P$98, IF( H32 <= 25000,$P$101, $P$104)) + IF(H32 <= 10000,$P$107, IF( H32 <= 25000,$P$109,$P$111)) + IF(H32 <= 10000,$P$113, IF( H32 <= 25000,$P$114,$P$115)) + IF(H32 <= 10000,$P$116, IF( H32 <= 25000,$P$117,$P$118)) +$P$119 + IF(H32 <= 10000,$P$120, IF( H32 <= 25000,$P$121, $P$122)) -> 4182.0515 | N32: =SUM($M$16:M32) -> 160666.63 | O32: =K32-M32 -> 70567.948 | P32: =SUM($O$16:O32) -> 512083.37
A33: Azure SQL database | B33: Stockage données | D33: =P85 -> 70 | G33: Mois 18 | H33: 18500 | I33: 0.1 | J33: =(H33-H32) * 30 + (H32 * I33) * 50 -> 117500 | K33: =J33*0.65 -> 76375 | L33: =SUM($K$15:K33) -> 749125 | M33: =$D$51 + IF(H33 <= 10000,$P$98, IF( H33 <= 25000,$P$101, $P$104)) + IF(H33 <= 10000,$P$107, IF( H33 <= 25000,$P$109,$P$111)) + IF(H33 <= 10000,$P$113, IF( H33 <= 25000,$P$114,$P$115)) + IF(H33 <= 10000,$P$116, IF( H33 <= 25000,$P$117,$P$118)) +$P$119 + IF(H33 <= 10000,$P$120, IF( H33 <= 25000,$P$121, $P$122)) -> 4182.0515 | N33: =SUM($M$16:M33) -> 164848.68 | O33: =K33-M33 -> 72192.948 | P33: =SUM($O$16:O33) -> 584276.32
A34: Azure Account Storage | B34: Stockage données | D34: =P88 -> 1.81 | F34: Année 2 post développement | G34: Mois 19 | H34: 19400 | I34: 0.1 | J34: =(H34-H33) * 30 + (H33 * I34) * 50 -> 119500 | K34: =J34*0.65 -> 77675 | L34: =SUM($K$15:K34) -> 826800 | M34: =$D$51 + IF(H34 <= 10000,$P$98, IF( H34 <= 25000,$P$101, $P$104)) + IF(H34 <= 10000,$P$107, IF( H34 <= 25000,$P$109,$P$111)) + IF(H34 <= 10000,$P$113, IF( H34 <= 25000,$P$114,$P$115)) + IF(H34 <= 10000,$P$116, IF( H34 <= 25000,$P$117,$P$118)) +$P$119 + IF(H34 <= 10000,$P$120, IF( H34 <= 25000,$P$121, $P$122)) -> 4182.0515 | N34: =SUM($M$16:M34) -> 169030.73 | O34: =K34-M34 -> 73492.948 | P34: =SUM($O$16:O34) -> 657769.27
A35: Azure App service | B35: Hébergement API | D35: =P91 -> 69 | G35: Mois 20 | H35: 20300 | I35: 0.1 | J35: =(H35-H34) * 30 + (H34 * I35) * 50 -> 124000 | K35: =J35*0.65 -> 80600 | L35: =SUM($K$15:K35) -> 907400 | M35: =$D$51 + IF(H35 <= 10000,$P$98, IF( H35 <= 25000,$P$101, $P$104)) + IF(H35 <= 10000,$P$107, IF( H35 <= 25000,$P$109,$P$111)) + IF(H35 <= 10000,$P$113, IF( H35 <= 25000,$P$114,$P$115)) + IF(H35 <= 10000,$P$116, IF( H35 <= 25000,$P$117,$P$118)) +$P$119 + IF(H35 <= 10000,$P$120, IF( H35 <= 25000,$P$121, $P$122)) -> 4182.0515 | N35: =SUM($M$16:M35) -> 173212.78 | O35: =K35-M35 -> 76417.948 | P35: =SUM($O$16:O35) -> 734187.22
A36: Azure Key Vault | B36: Sécurité des clés API | D36: =P92 -> 5 | G36: Mois 21 | H36: 21100 | I36: 0.1 | J36: =(H36-H35) * 30 + (H35 * I36) * 50 -> 125500 | K36: =J36*0.65 -> 81575 | L36: =SUM($K$15:K36) -> 988975 | M36: =$D$51 + IF(H36 <= 10000,$P$98, IF( H36 <= 25000,$P$101, $P$104)) + IF(H36 <= 10000,$P$107, IF( H36 <= 25000,$P$109,$P$111)) + IF(H36 <= 10000,$P$113, IF( H36 <= 25000,$P$114,$P$115)) + IF(H36 <= 10000,$P$116, IF( H36 <= 25000,$P$117,$P$118)) +$P$119 + IF(H36 <= 10000,$P$120, IF( H36 <= 25000,$P$121, $P$122)) -> 4182.0515 | N36: =SUM($M$16:M36) -> 177394.83 | O36: =K36-M36 -> 77392.948 | P36: =SUM($O$16:O36) -> 811580.17
A37: Azure Monitoring | B37: Monitoring log, performance, alertes | D37: =P93 -> 37 | G37: Mois 22 | H37: 21900 | I37: 0.1 | J37: =(H37-H36) * 30 + (H36 * I37) * 50 -> 129500 | K37: =J37*0.65 -> 84175 | L37: =SUM($K$15:K37) -> 1073150 | M37: =$D$51 + IF(H37 <= 10000,$P$98, IF( H37 <= 25000,$P$101, $P$104)) + IF(H37 <= 10000,$P$107, IF( H37 <= 25000,$P$109,$P$111)) + IF(H37 <= 10000,$P$113, IF( H37 <= 25000,$P$114,$P$115)) + IF(H37 <= 10000,$P$116, IF( H37 <= 25000,$P$117,$P$118)) +$P$119 + IF(H37 <= 10000,$P$120, IF( H37 <= 25000,$P$121, $P$122)) -> 4182.0515 | N37: =SUM($M$16:M37) -> 181576.89 | O37: =K37-M37 -> 79992.948 | P37: =SUM($O$16:O37) -> 891573.11
A38: Total | D38: =SUM(D31:D37) -> 542.81 | G38: Mois 23 | H38: 22600 | I38: 0.1 | J38: =(H38-H37) * 30 + (H37 * I38) * 50 -> 130500 | K38: =J38*0.65 -> 84825 | L38: =SUM($K$15:K38) -> 1157975 | M38: =$D$51 + IF(H38 <= 10000,$P$98, IF( H38 <= 25000,$P$101, $P$104)) + IF(H38 <= 10000,$P$107, IF( H38 <= 25000,$P$109,$P$111)) + IF(H38 <= 10000,$P$113, IF( H38 <= 25000,$P$114,$P$115)) + IF(H38 <= 10000,$P$116, IF( H38 <= 25000,$P$117,$P$118)) +$P$119 + IF(H38 <= 10000,$P$120, IF( H38 <= 25000,$P$121, $P$122)) -> 4182.0515 | N38: =SUM($M$16:M38) -> 185758.94 | O38: =K38-M38 -> 80642.948 | P38: =SUM($O$16:O38) -> 972216.06
A39: Phase de production | G39: Mois 24 | H39: 23200 | I39: 0.1 | J39: =(H39-H38) * 30 + (H38 * I39) * 50 -> 131000 | K39: =J39*0.65 -> 85150 | L39: =SUM($K$15:K39) -> 1243125 | M39: =$D$51 + IF(H39 <= 10000,$P$98, IF( H39 <= 25000,$P$101, $P$104)) + IF(H39 <= 10000,$P$107, IF( H39 <= 25000,$P$109,$P$111)) + IF(H39 <= 10000,$P$113, IF( H39 <= 25000,$P$114,$P$115)) + IF(H39 <= 10000,$P$116, IF( H39 <= 25000,$P$117,$P$118)) +$P$119 + IF(H39 <= 10000,$P$120, IF( H39 <= 25000,$P$121, $P$122)) -> 4182.0515 | N39: =SUM($M$16:M39) -> 189940.99 | O39: =K39-M39 -> 80967.948 | P39: =SUM($O$16:O39) -> 1053184
A40: Azure Machine learning | B40: Inférence, déploiement modèle IA, GPU, CPU | D40: variable | G40: Mois 25 | H40: 23800 | I40: 0.1 | J40: =(H40-H39) * 30 + (H39 * I40) * 50 -> 134000 | K40: =J40*0.65 -> 87100 | L40: =SUM($K$15:K40) -> 1330225 | M40: =$D$51 + IF(H40 <= 10000,$P$98, IF( H40 <= 25000,$P$101, $P$104)) + IF(H40 <= 10000,$P$107, IF( H40 <= 25000,$P$109,$P$111)) + IF(H40 <= 10000,$P$113, IF( H40 <= 25000,$P$114,$P$115)) + IF(H40 <= 10000,$P$116, IF( H40 <= 25000,$P$117,$P$118)) +$P$119 + IF(H40 <= 10000,$P$120, IF( H40 <= 25000,$P$121, $P$122)) -> 4182.0515 | N40: =SUM($M$16:M40) -> 194123.04 | O40: =K40-M40 -> 82917.948 | P40: =SUM($O$16:O40) -> 1136102
G41: Mois 26 | H41: 24400 | I41: 0.1 | J41: =(H41-H40) * 30 + (H40 * I41) * 50 -> 137000 | K41: =J41*0.65 -> 89050 | L41: =SUM($K$15:K41) -> 1419275 | M41: =$D$51 + IF(H41 <= 10000,$P$98, IF( H41 <= 25000,$P$101, $P$104)) + IF(H41 <= 10000,$P$107, IF( H41 <= 25000,$P$109,$P$111)) + IF(H41 <= 10000,$P$113, IF( H41 <= 25000,$P$114,$P$115)) + IF(H41 <= 10000,$P$116, IF( H41 <= 25000,$P$117,$P$118)) +$P$119 + IF(H41 <= 10000,$P$120, IF( H41 <= 25000,$P$121, $P$122)) -> 4182.0515 | N41: =SUM($M$16:M41) -> 198305.09 | O41: =K41-M41 -> 84867.948 | P41: =SUM($O$16:O41) -> 1220969.9
A42: Azure SQL database | B42: Stockage données | D42: variable | G42: Mois 27 | H42: 25000 | I42: 0.1 | J42: =(H42-H41) * 30 + (H41 * I42) * 50 -> 140000 | K42: =J42*0.65 -> 91000 | L42: =SUM($K$15:K42) -> 1510275 | M42: =$D$51 + IF(H42 <= 10000,$P$98, IF( H42 <= 25000,$P$101, $P$104)) + IF(H42 <= 10000,$P$107, IF( H42 <= 25000,$P$109,$P$111)) + IF(H42 <= 10000,$P$113, IF( H42 <= 25000,$P$114,$P$115)) + IF(H42 <= 10000,$P$116, IF( H42 <= 25000,$P$117,$P$118)) +$P$119 + IF(H42 <= 10000,$P$120, IF( H42 <= 25000,$P$121, $P$122)) -> 4182.0515 | N42: =SUM($M$16:M42) -> 202487.14 | O42: =K42-M42 -> 86817.948 | P42: =SUM($O$16:O42) -> 1307787.9
A43: Azure Account Storage | B43: Stockage données | D43: variable | G43: Mois 28 | H43: 25400 | I43: 0.1 | J43: =(H43-H42) * 30 + (H42 * I43) * 50 -> 137000 | K43: =J43*0.65 -> 89050 | L43: =SUM($K$15:K43) -> 1599325 | M43: =$D$51 + IF(H43 <= 10000,$P$98, IF( H43 <= 25000,$P$101, $P$104)) + IF(H43 <= 10000,$P$107, IF( H43 <= 25000,$P$109,$P$111)) + IF(H43 <= 10000,$P$113, IF( H43 <= 25000,$P$114,$P$115)) + IF(H43 <= 10000,$P$116, IF( H43 <= 25000,$P$117,$P$118)) +$P$119 + IF(H43 <= 10000,$P$120, IF( H43 <= 25000,$P$121, $P$122)) -> 4697.5815 | N43: =SUM($M$16:M43) -> 207184.72 | O43: =K43-M43 -> 84352.418 | P43: =SUM($O$16:O43) -> 1392140.3
A44: Azure App service | B44: Hébergement API | D44: variable | G44: Mois 29 | H44: 25800 | I44: 0.1 | J44: =(H44-H43) * 30 + (H43 * I44) * 50 -> 139000 | K44: =J44*0.65 -> 90350 | L44: =SUM($K$15:K44) -> 1689675 | M44: =$D$51 + IF(H44 <= 10000,$P$98, IF( H44 <= 25000,$P$101, $P$104)) + IF(H44 <= 10000,$P$107, IF( H44 <= 25000,$P$109,$P$111)) + IF(H44 <= 10000,$P$113, IF( H44 <= 25000,$P$114,$P$115)) + IF(H44 <= 10000,$P$116, IF( H44 <= 25000,$P$117,$P$118)) +$P$119 + IF(H44 <= 10000,$P$120, IF( H44 <= 25000,$P$121, $P$122)) -> 4697.5815 | N44: =SUM($M$16:M44) -> 211882.31 | O44: =K44-M44 -> 85652.418 | P44: =SUM($O$16:O44) -> 1477792.7
A45: Azure Key Vault | B45: Sécurité des clés API | D45: =P119 -> 5 | G45: Mois 30 | H45: 26200 | I45: 0.1 | J45: =(H45-H44) * 30 + (H44 * I45) * 50 -> 141000 | K45: =J45*0.65 -> 91650 | L45: =SUM($K$15:K45) -> 1781325 | M45: =$D$51 + IF(H45 <= 10000,$P$98, IF( H45 <= 25000,$P$101, $P$104)) + IF(H45 <= 10000,$P$107, IF( H45 <= 25000,$P$109,$P$111)) + IF(H45 <= 10000,$P$113, IF( H45 <= 25000,$P$114,$P$115)) + IF(H45 <= 10000,$P$116, IF( H45 <= 25000,$P$117,$P$118)) +$P$119 + IF(H45 <= 10000,$P$120, IF( H45 <= 25000,$P$121, $P$122)) -> 4697.5815 | N45: =SUM($M$16:M45) -> 216579.89 | O45: =K45-M45 -> 86952.418 | P45: =SUM($O$16:O45) -> 1564745.1
A46: Azure Monitoring | B46: Monitoring log, performance, alertes | D46: variable | F46: Année 3 post développement | G46: Mois 31 | H46: 26500 | I46: 0.1 | J46: =(H46-H45) * 30 + (H45 * I46) * 50 -> 140000 | K46: =J46*0.65 -> 91000 | L46: =SUM($K$15:K46) -> 1872325 | M46: =$D$51 + IF(H46 <= 10000,$P$98, IF( H46 <= 25000,$P$101, $P$104)) + IF(H46 <= 10000,$P$107, IF( H46 <= 25000,$P$109,$P$111)) + IF(H46 <= 10000,$P$113, IF( H46 <= 25000,$P$114,$P$115)) + IF(H46 <= 10000,$P$116, IF( H46 <= 25000,$P$117,$P$118)) +$P$119 + IF(H46 <= 10000,$P$120, IF( H46 <= 25000,$P$121, $P$122)) -> 4697.5815 | N46: =SUM($M$16:M46) -> 221277.47 | O46: =K46-M46 -> 86302.418 | P46: =SUM($O$16:O46) -> 1651047.5
A47: Total | G47: Mois 32 | H47: 26800 | I47: 0.1 | J47: =(H47-H46) * 30 + (H46 * I47) * 50 -> 141500 | K47: =J47*0.65 -> 91975 | L47: =SUM($K$15:K47) -> 1964300 | M47: =$D$51 + IF(H47 <= 10000,$P$98, IF( H47 <= 25000,$P$101, $P$104)) + IF(H47 <= 10000,$P$107, IF( H47 <= 25000,$P$109,$P$111)) + IF(H47 <= 10000,$P$113, IF( H47 <= 25000,$P$114,$P$115)) + IF(H47 <= 10000,$P$116, IF( H47 <= 25000,$P$117,$P$118)) +$P$119 + IF(H47 <= 10000,$P$120, IF( H47 <= 25000,$P$121, $P$122)) -> 4697.5815 | N47: =SUM($M$16:M47) -> 225975.05 | O47: =K47-M47 -> 87277.418 | P47: =SUM($O$16:O47) -> 1738324.9
A48: Maintenance | G48: Mois 33 | H48: 27100 | I48: 0.1 | J48: =(H48-H47) * 30 + (H47 * I48) * 50 -> 143000 | K48: =J48*0.65 -> 92950 | L48: =SUM($K$15:K48) -> 2057250 | M48: =$D$51 + IF(H48 <= 10000,$P$98, IF( H48 <= 25000,$P$101, $P$104)) + IF(H48 <= 10000,$P$107, IF( H48 <= 25000,$P$109,$P$111)) + IF(H48 <= 10000,$P$113, IF( H48 <= 25000,$P$114,$P$115)) + IF(H48 <= 10000,$P$116, IF( H48 <= 25000,$P$117,$P$118)) +$P$119 + IF(H48 <= 10000,$P$120, IF( H48 <= 25000,$P$121, $P$122)) -> 4697.5815 | N48: =SUM($M$16:M48) -> 230672.63 | O48: =K48-M48 -> 88252.418 | P48: =SUM($O$16:O48) -> 1826577.4
A49: Développement RH | D49: =D25 / 5 -> 22074 | G49: Mois 34 | H49: 27300 | I49: 0.1 | J49: =(H49-H48) * 30 + (H48 * I49) * 50 -> 141500 | K49: =J49*0.65 -> 91975 | L49: =SUM($K$15:K49) -> 2149225 | M49: =$D$51 + IF(H49 <= 10000,$P$98, IF( H49 <= 25000,$P$101, $P$104)) + IF(H49 <= 10000,$P$107, IF( H49 <= 25000,$P$109,$P$111)) + IF(H49 <= 10000,$P$113, IF( H49 <= 25000,$P$114,$P$115)) + IF(H49 <= 10000,$P$116, IF( H49 <= 25000,$P$117,$P$118)) +$P$119 + IF(H49 <= 10000,$P$120, IF( H49 <= 25000,$P$121, $P$122)) -> 4697.5815 | N49: =SUM($M$16:M49) -> 235370.21 | O49: =K49-M49 -> 87277.418 | P49: =SUM($O$16:O49) -> 1913854.8
A50: Développement matériel et logistique | D50: =D38 -> 542.81 | G50: Mois 35 | H50: 27500 | I50: 0.1 | J50: =(H50-H49) * 30 + (H49 * I50) * 50 -> 142500 | K50: =J50*0.65 -> 92625 | L50: =SUM($K$15:K50) -> 2241850 | M50: =$D$51 + IF(H50 <= 10000,$P$98, IF( H50 <= 25000,$P$101, $P$104)) + IF(H50 <= 10000,$P$107, IF( H50 <= 25000,$P$109,$P$111)) + IF(H50 <= 10000,$P$113, IF( H50 <= 25000,$P$114,$P$115)) + IF(H50 <= 10000,$P$116, IF( H50 <= 25000,$P$117,$P$118)) +$P$119 + IF(H50 <= 10000,$P$120, IF( H50 <= 25000,$P$121, $P$122)) -> 4697.5815 | N50: =SUM($M$16:M50) -> 240067.8 | O50: =K50-M50 -> 87927.418 | P50: =SUM($O$16:O50) -> 2001782.2
A51: Total (15% du développement total) | D51: =SUM(D49:D50) * 0.15 -> 3392.5215 | G51: Mois 36 | H51: 27700 | I51: 0.1 | J51: =(H51-H50) * 30 + (H50 * I51) * 50 -> 143500 | K51: =J51*0.65 -> 93275 | L51: =SUM($K$15:K51) -> 2335125 | M51: =$D$51 + IF(H51 <= 10000,$P$98, IF( H51 <= 25000,$P$101, $P$104)) + IF(H51 <= 10000,$P$107, IF( H51 <= 25000,$P$109,$P$111)) + IF(H51 <= 10000,$P$113, IF( H51 <= 25000,$P$114,$P$115)) + IF(H51 <= 10000,$P$116, IF( H51 <= 25000,$P$117,$P$118)) +$P$119 + IF(H51 <= 10000,$P$120, IF( H51 <= 25000,$P$121, $P$122)) -> 4697.5815 | N51: =SUM($M$16:M51) -> 244765.38 | O51: =K51-M51 -> 88577.418 | P51: =SUM($O$16:O51) -> 2090359.6
A83: Détails des coûts estimés pendant la phase de développement
...

Sheet Risque
A1: ID | B1: Titre | C1: Facteurs de risque | D1: Risque (événement redouté) | E1: Conséquence | F1: Conséquences (en coût, délai, qualité, satisfaction client) | G1: Impact (1 à5) | H1: Probabilité (1 à 5) | I1: Criticité (impact*prob) | J1: Actions de prévention (pour éviter l'événement redouté) | K1: Action de correction (si événement redouté avéré)
A2: R1 | B2: Compétence de l’équipe IA | C2: Étant donné que l’équipe IA comprend un data scientist junior, | D2: Si ce data scientist manque d’expérience sur ce projet complexe, | E2: Alors des erreurs de modélisation peuvent arriver et le développement pourrait prendre plus de temps ce qui impacterait le délai et la qualité. | F2: Délai / qualité | G2: 3 | H2: 4 | I2: =G2*H2 -> 12 | J2: Vérifier si le data scientist à déjà réalisé des tâches similaire, lui fournir un mentorat par un senior, revues de code et de notebooks, pair programming | K2: Revue complète du modèle, appui technique externe | N2: Délai | O2: 2
A3: R2 | B3: Charge multi-projets | C3: Étant donné que l’équipe travaille sur plusieurs projets en parallèle, | D3: Si l’organisation du travail n’est pas optimisée | E3: Alors une baisse de productivité et des retards cumulés vont affecter délai, qualité et satisfaction. | F3: Délai / qualité / satisfaction | G3: 2 | H3: 2 | I3: =G3*H3 -> 4 | J3: Planification précise des ressources, focus de l'équipe par sprint, ajout de marges pour gérer les éventuels imprévus liés au second projet | K3: Réaffectation des priorités en accord avec les parties prenantes, recrutement temporaire ou ajustement planning | N3: Qualité | O3: 6
A4: R3 | B4: Qualité des données d’entraînement | C4: Étant donné que les données d’entraînement peuvent être biaisées, | D4: Si un biais de recommandation se produit (ex : discrimination des styles, morphologie ou genre), | E4: Alors les utilisateurs peuvent se sentir discriminés, et perdre confiance et satisfaction. | F4: Qualité / satisfaction / réputation | G4: 4 | H4: 2 | I4: =G4*H4 -> 8 | J4: Diversification du dataset, audit IA, tests, comité éthique | K4: Réentraînement du modèle avec données plus équilibrées | N4: Satisfaction | O4: 6
A5: R4 | B5: Données sensibles | C5: Étant donné que les données d’images utilisateurs sont sensibles, | D5: Si une fuite de ces données survient, | E5: Alors la vie privée des utilisateurs est atteinte, l’image de marque est dégradée, les utilisateurs peuvent perdre confiance, et il y a un risque de sanction de la CNIL. | F5: Coût / satisfaction / réputation | G5: 5 | H5: 3 | I5: =G5*H5 -> 15 | J5: Stockage sécurisé Azure, chiffrement des données, anonymisation, stockage des photos utilisateurs uniquement pendant la phase de prédiction, audits de régulier de sécurité | K5: Alerte DPO, notification CNIL, prévenir les utilisateurs de la fuite de leur données et des mesures mises en place, purge et rotation des clés de chiffrement | N5: Réputation | O5: 5
A6: R5 | B6: Conformité réglementaire | C6: Étant donné que la réglementation RGPD impose des contraintes strictes, | D6: Si il y a une non-conformité, | E6: Alors des amendes, une perte de confiance des partenaires et clients, ainsi que des pertes d’exploitation peuvent survenir, affectant coût et réputation. | F6: Coût / réputation | G6: 4 | H6: 2 | I6: =G6*H6 -> 8 | J6: Consentement explicite, registre CNIL, implication du DPO pour aider l'équipe à faire respecter les grand principes du RGPD. | K6: Mise à jour et correction des traitements et de la documentation RGPD | N6: Cout | O6: 6
A7: R6 | B7: Expérience utilisateur | C7: Étant donné que l’expérience utilisateur dépend des recommandations, | D7: Si les recommandations sont peu pertinentes, | E7: Alors la satisfaction baisse, l'application est mal évaéluée, et peuet être désinstallée. | F7: Qualité / satisfaction | G7: 4 | H7: 2 | I7: =G7*H7 -> 8 | J7: Tests utilisateurs, boucles de feedback, amélioration continue en tenant compte des retours utilisateurs | K7: Ajustement de l’algorithme, recalibrage des filtres
A8: R7 | B8: Panne infrastructures | C8: Étant donné que l'application dépend des services du cloud Azure, | D8: Si une panne survient, | E8: Alors l’application est inutilisable, générant une perte de revenus temporaire. | F8: Qualité / coût / satisfaction | G8: 3 | H8: 2 | I8: =G8*H8 -> 6 | J8: Permettre une redondance régionale via Azure, mise en place d'un contrat SLA. | K8: Basculer l'application sur un environnement de secours, avertir les utlisateurs de la panne, prendre contact avec le service client d'azure
A9: R8 | B9: Sécurité des paiements | C9: Étant donné que la sécurité des paiements est critique, | D9: Si une faille dans le module paiement est exploitée, | E9: Alors des données bancaires peuvent fuir, avec sanctions à la clé, et une perte de confiance des utilisateurs | F9: Coût / réputation | G9: 5 | H9: 2 | I9: =G9*H9 -> 10 | J9: Intégration de prestataire certifié PCI-DSS (ex : Stripe) | K9: Suspension du service, audit sécurité complet
A10: R9 | B10: Qualité des images en entrée | C10: Étant donné que la qualité des images d'entrée influe sur la détection, | D10: Si les photos sont floues ou non conformes, | E10: Alors les recommandations seront mauvaises, impactant la qualité de la recommandataion et dégraderait la qualité percue du service | F10: Qualité / satisfaction | G10: 4 | H10: 2 | I10: =G10*H10 -> 8 | J10: Aide à la prise de photo (guidelines, recadrage automatique) | K10: Réentrainement du modèle ou amélioration du preprocessing
A11: R10 | B11: Éthique / transparence IA | C11: Étant donné que la transparence de l’IA est importante pour mettre les utilisateurs en confiance, | D11: Si les recommandations manquent d’explication ou ne sont pas suffisament claires pour l'utilisateurs | E11: Alors les utilisateurs pourraient se méfier et abandonner l’application. | F11: Satisfaction / réputation | G11: 2 | H11: 2 | I11: =G11*H11 -> 4 | J11: Explicabilité du modèle, communication claire sur l’IA | K11: Ajout de messages explicatifs, FAQ dédiée
A12: R11 | B12: Coûts sous estimés | C12: Étant donné que les coûts des infrastructures dépendent du volume de données | D12: Si ces volumes ont mal été estimés ou si les tarifs évoluent pendant le projet | E12: Alors un dépassement du budget pourrait survenir | F12: Coût | G12: 3 | H12: 2 | I12: =G12*H12 -> 6 | J12: Simulation via Azure Pricing Calculator, suivi coûts, optimisation du choix d'infrastructures utilisées, prévision d'une marge | K12: Réduction temporaire des ressources, ajustement budgétaire, abandon de certaines fonctionnalités
A13: R12 | B13: Concurrence | C13: Étant donné que des concurrents travaillent sur des solutions similaires, | D13: Si un concurrent lance un produit similaire plus rapidement, | E13: Alors nous perdons notre avantage compétitif et des parts de marché. | F13: Coût | G13: 4 | H13: 3 | I13: =G13*H13 -> 12 | J13: Veille du marché continue, benchmark trimestriel, innovation continue | K13: Réorientation stratégique, ajout de fonctionnalités différenciantes

Sheet CNIL traitement 001
A1: Description du traitement n° ref-001
A2: Nom du traitement | B2: Gestion des comptes utilisateurs
A3: N° / RÉF | B3: ref-001
A4: Date de création du traitement | B4: 45958
A5: Mise à jour du traitement | B5: 45960
A6: Acteurs | B6: Nom | C6: Adresse | D6: Code Postal | E6: Ville | F6: Pays | G6: Téléphone | H6: Adresse mél
A7: Responsable du traitement | B7: Fashion-insta | C7: 12 rue saint Honoré | D7: 75001 | E7: Paris | F7: France | G7: 01-xx-xx-xx-xx | H7: contact@fashion-insta.com
A8: Délégué à la protection des données | B8: Valérie Maler | C8: 12 rue saint Honoré | D8: 75001 | E8: Paris | F8: France | G8: 01-xx-xx-xx-xx | H8: v-maler@fashion-insta.com
A9: Société du DPO (si celui-ci est externe) | B9: / | C9: / | D9: / | E9: / | F9: / | G9: / | H9: /
A10: Représentant | B10: Alicia Lerise | C10: 12 rue saint Honoré | D10: 75001 | E10: Paris | F10: France | G10: 01-xx-xx-xx-xx | H10: a-lerise@fashion-insta.com
A11: Responsable(s) conjoint(s) | B11: / | C11: / | D11: / | E11: / | F11: / | G11: / | H11: /
A12: Finalité(s) du traitement effectué
A13: Finalité principale | B13: Permettre la création, la gestion et la suppression d’un compte utilisateur sur l’application mobile Fashion-Insta.
A14: Sous-finalité 1 | B14: Authentifier les utilisateurs lors de la connexion (adresse mail + mot de passe).
A15: Sous-finalité 2 | B15: Gérer les informations du profil utilisateur (nom, prénom, préférences, historique des commandes).
A16: Sous-finalité 3 | B16: Permettre la récupération du mot de passe en cas d’oubli.
A17: Sous-finalité 4 | B17: Gérer la désactivation et la suppression du compte à la demande.
A18: Sous-finalité 5 | B18: Garantir la sécurité et la traçabilité des accès à l’application.
A19: Catégories de données personnelles concernées | B19: Description | E19: Durée de conservation
A20: État civil, identité, données d'identification, images… | B20: Nom, prénom, adresse e-mail, identifiant, mot de passe chiffré | E20: 3 ans après la dernière activité de l’utilisateur (ou suppression sur demande)
A21: Vie personnelle (habitudes de vie, situation familiale, etc.) | B21: Préférences de style, marques favorites, historique de navigation sur l’app | E21: 3 ans après la dernière activité de l’utilisateur (ou suppression sur demande)
A22: Informations d'ordre économique et financier (revenus, situation financière, situation fiscale, etc.) | B22: Historique d’achats (liens vers système de commande) | E22: 10 ans à compter de la transaction (pour des fins de comptabilité)
A23: Données de connexion (adress IP, logs, etc.) | B23: Adresse IP, logs de connexion | E23: 1 an
A24: Données de localisation (déplacements, données GPS, GSM, etc.) | B24: Non applicable
A25: Numéro de Sécurité Sociale (ou NIR) | B25: Non applicable
A26: Données sensibles | B26: Description | E26: Durée de conservation
A27: Données révélant l'origine raciale ou ethnique
A28: Données révélant les opinions politiques
A29: Données révélant les convictions religieuses ou philosophiques
A30: Données révélant l'appartenance syndicale
A31: Données génétiques
A32: Données biométriques aux fins d'identifier une personne physique de manière unique
A33: Données concernant la santé
A34: Données concernant la vie sexuelle ou l'orientation sexuelle
A35: Données relatives à des condamnations pénales ou infractions
A36: Catégories de personnes concernées | B36: Description | E36: Précisions
A37: Catégorie de personnes 1 | B37: Client
A38: Destinataires | B38: Type de destinataire | E38: Précisions
A39: Destinataire 1 | B39: Service internet IT | E39: Gestion technique des comptes
A40: Destinataire 2 | B40: Prestataire cloud | E40: Microsoft Azure
...

Sheet CNIL traitement 002
A1: Description du traitement n° ref-002
A2: Nom du traitement | B2: Recommandation
A3: N° / RÉF | B3: ref-002
A4: Date de création du traitement | B4: 45958
A5: Mise à jour du traitement | B5: 45960
A6: Acteurs | B6: Nom | C6: Adresse | D6: Code Postal | E6: Ville | F6: Pays | G6: Téléphone | H6: Adresse mél
A7: Responsable du traitement | B7: Fashion-insta | C7: 12 rue saint Honoré | D7: 75001 | E7: Paris | F7: France | G7: 01-xx-xx-xx-xx | H7: contact@fashion-insta.com
A8: Délégué à la protection des données | B8: Valérie Maler | C8: 12 rue saint Honoré | D8: 75001 | E8: Paris | F8: France | G8: 01-xx-xx-xx-xx | H8: v-maler@fashion-insta.com
A9: Société du DPO (si celui-ci est externe) | B9: / | C9: / | D9: / | E9: / | F9: / | G9: / | H9: /
A10: Représentant | B10: Alicia Lerise | C10: 12 rue saint Honoré | D10: 75001 | E10: Paris | F10: France | G10: 01-xx-xx-xx-xx | H10: a-lerise@fashion-insta.com
A11: Responsable(s) conjoint(s) | B11: / | C11: / | D11: / | E11: / | F11: / | G11: / | H11: /
A12: Finalité(s) du traitement effectué
A13: Finalité principale | B13: Fournir des recommandations de mode personnalisées basées sur les photos et préférences des utilisateurs.
A14: Sous-finalité 1 | B14: Analyser les images uploadées pour détecter styles, couleurs, et motifs.
A15: Sous-finalité 2 | B15: Utiliser les préférences pour affiner les recommandations.
A16: Sous-finalité 3
A17: Sous-finalité 4
A18: Catégories de données personnelles concernées | B18: Description | E18: Durée de conservation
A19: État civil, identité, données d'identification, images… | B19: Images utilisateurs (photos uploadées) | E19: 1 an après la dernière activité ou suppression immédiate sur demande
A20: Vie personnelle (habitudes de vie, situation familiale, etc.) | B20: Préférences de style, marques favorites, historique de navigation sur l’app | E20: 3 ans après la dernière activité de l’utilisateur ou suppression sur demande
A21: Informations d'ordre économique et financier (revenus, situation financière, situation fiscale, etc.) | B21: Non applicable
A22: Données de connexion (adress IP, logs, etc.) | B22: Adresse IP, logs de connexion | E22: 1 an
A23: Données de localisation (déplacements, données GPS, GSM, etc.) | B23: Non applicable
A24: Numéro de Sécurité Sociale (ou NIR) | B24: Non applicable
A25: Données sensibles | B25: Description | E25: Durée de conservation
A26: Données révélant l'origine raciale ou ethnique | B26: Les caractéristiques visibles sur les photos peuvent permettre une identification implicite ou explicite de l'origine ethnique ou raciale. | E26: 1 an après la dernière activité ou suppression immédiate sur demande
A27: Données révélant les opinions politiques
A28: Données révélant les convictions religieuses ou philosophiques | B28: Certains vêtements, accessoires ou symboles présents sur les photos pourraient laisser apparaître des informations révélatrices de la religion. | E28: 1 an après la dernière activité ou suppression immédiate sur demande
A29: Données révélant l'appartenance syndicale
A30: Données génétiques
A31: Données biométriques aux fins d'identifier une personne physique de manière unique | B31: La présence du visage sur les photos constitue un élément permettant d'identifier la personne. | E31: 1 an après la dernière activité ou suppression immédiate sur demande
A32: Données concernant la santé | B32: Certains éléments visibles sur les photos pourraient indiquer diverses informations sur l'état de santé de l'utilisateur. | E32: 1 an après la dernière activité ou suppression immédiate sur demande
A33: Données concernant la vie sexuelle ou l'orientation sexuelle
A34: Données relatives à des condamnations pénales ou infractions
A35: Catégories de personnes concernées | B35: Description | E35: Précisions
A36: Catégorie de personnes 1 | B36: Client
A37: Destinataires | B37: Type de destinataire | E37: Précisions
A38: Destinataire 1 | B38: Service interne IT | E38: Gestion technique des comptes
A39: Destinataire 2 | B39: Service interne Data | E39: Acces aux données utilisateurs (images, préférences) pour les tâches IA (amélioration, maintenance du système de recommandation avec réentrainement régulier du modèle)
A40: Destinataire 3 | B40: Prestataire IA | E40: Acces aux données utilisateurs (images, préférences) pour les tâches IA (amélioration, maintenance du système de recommandation avec réentrainement régulier du modèle)
...
